<?xml version="1.0" encoding="utf-8"?>
<!-- This URDF was automatically created by SolidWorks to URDF Exporter! Originally created by Stephen Brawner (brawner@gmail.com) 
     Commit Version: 1.6.0-4-g7f85cfe  Build Version: 1.6.7995.38578
     For more information, please see http://wiki.ros.org/sw_urdf_exporter -->
<robot
  name="Scorpion_V3_FINAL">
  <link
    name="base_link">
    <inertial>
      <origin
        xyz="-0.0320958838264929 -0.000522598904331387 0.0404450801333069"
        rpy="0 0 0" />
      <mass
        value="0.719448434866353" />
      <inertia
        ixx="0.000578774154998931"
        ixy="-7.70838049246388E-06"
        ixz="2.46751272255456E-06"
        iyy="0.00102219012006826"
        iyz="-9.99042156873633E-07"
        izz="0.00142499608206966" />
    </inertial>
    <visual>
      <origin
        xyz="0 0 0"
        rpy="0 0 0" />
      <geometry>
        <mesh
          filename="package://Scorpion_V3_FINAL/meshes/base_link.stl" />
      </geometry>
      <material
        name="">
        <color
          rgba="0 0.501960784313725 1 1" />
      </material>
    </visual>
    <collision>
      <origin
        xyz="0 0 0"
        rpy="0 0 0" />
      <geometry>
        <mesh
          filename="package://Scorpion_V3_FINAL/meshes/base_link.stl" />
      </geometry>
    </collision>
  </link>
  <link
    name="CoxisRU">
    <inertial>
      <origin
        xyz="0.00040067192611086 -0.0299835659979626 -0.0325440529969379"
        rpy="0 0 0" />
      <mass
        value="0.0489064187126159" />
      <inertia
        ixx="1.55993106391618E-05"
        ixy="2.12164234721843E-06"
        ixz="-3.89057430497465E-08"
        iyy="1.59517568039545E-05"
        iyz="-2.2284455366756E-06"
        izz="1.49560866269211E-05" />
    </inertial>
    <visual>
      <origin
        xyz="0 0 0"
        rpy="0 0 0" />
      <geometry>
        <mesh
          filename="package://Scorpion_V3_FINAL/meshes/CoxisRU.stl" />
      </geometry>
      <material
        name="">
        <color
          rgba="0 0.27843137254902 0.890196078431372 1" />
      </material>
    </visual>
    <collision>
      <origin
        xyz="0 0 0"
        rpy="0 0 0" />
      <geometry>
        <mesh
          filename="package://Scorpion_V3_FINAL/meshes/CoxisRU.stl" />
      </geometry>
    </collision>
  </link>
  <joint
    name="CoxisRU_joint"
    type="revolute">
    <origin
      xyz="0.0906140007097903 -0.0627712737240257 -0.0159000000000001"
      rpy="3.14159265358979 0 3.14159265358979" />
    <parent
      link="base_link" />
    <child
      link="CoxisRU" />
    <axis
      xyz="0 0 -1" />
    <limit
      lower="-0.785"
      upper="0.785"
      effort="100"
      velocity="100" />
  </joint>
  <link
    name="FemurRU">
    <inertial>
      <origin
        xyz="0.030862280472353 -0.017776359432272 -0.0352571158653482"
        rpy="0 0 0" />
      <mass
        value="0.104163087334194" />
      <inertia
        ixx="4.88465189543408E-05"
        ixy="-2.71667554112254E-07"
        ixz="-4.45658116386361E-07"
        iyy="4.57411426428311E-05"
        iyz="-1.55638237514164E-05"
        izz="2.33225615574816E-05" />
    </inertial>
    <visual>
      <origin
        xyz="0 0 0"
        rpy="0 0 0" />
      <geometry>
        <mesh
          filename="package://Scorpion_V3_FINAL/meshes/FemurRU.stl" />
      </geometry>
      <material
        name="">
        <color
          rgba="0.498039215686275 0.498039215686275 0.498039215686275 1" />
      </material>
    </visual>
    <collision>
      <origin
        xyz="0 0 0"
        rpy="0 0 0" />
      <geometry>
        <mesh
          filename="package://Scorpion_V3_FINAL/meshes/FemurRU.stl" />
      </geometry>
    </collision>
  </link>
  <joint
    name="FemurRU_joint"
    type="revolute">
    <origin
      xyz="-0.0315424983760021 -0.0594585605379239 -0.0335000009091112"
      rpy="-1.57079632679489 0 0" />
    <parent
      link="CoxisRU" />
    <child
      link="FemurRU" />
    <axis
      xyz="0.999847695156391 0 -0.0174524064372811" />
    <limit
      lower="-3.14"
      upper="3.14"
      effort="100"
      velocity="100" />
  </joint>
  <link
    name="TibiaRU">
    <inertial>
      <origin
        xyz="0.00922075761477547 0.029546552697005 -0.078196132462836"
        rpy="0 0 0" />
      <mass
        value="0.112635357132419" />
      <inertia
        ixx="6.80126782213861E-05"
        ixy="5.55667502959891E-07"
        ixz="3.862145640174E-06"
        iyy="4.7011610789482E-05"
        iyz="-4.20862627108641E-06"
        izz="3.58416838228086E-05" />
    </inertial>
    <visual>
      <origin
        xyz="0 0 0"
        rpy="0 0 0" />
      <geometry>
        <mesh
          filename="package://Scorpion_V3_FINAL/meshes/TibiaRU.stl" />
      </geometry>
      <material
        name="">
        <color
          rgba="0.196078431372549 0.913725490196078 1 1" />
      </material>
    </visual>
    <collision>
      <origin
        xyz="0 0 0"
        rpy="0 0 0" />
      <geometry>
        <mesh
          filename="package://Scorpion_V3_FINAL/meshes/TibiaRU.stl" />
      </geometry>
    </collision>
  </link>
  <joint
    name="TibiaRU_joint"
    type="revolute">
    <origin
      xyz="-0.00121165513146662 -0.0355527188621393 -0.0694156759914683"
      rpy="0 0 -1.57079632679489" />
    <parent
      link="FemurRU" />
    <child
      link="TibiaRU" />
    <axis
      xyz="0 0.999847695156391 -0.0174524064372866" />
    <limit
      lower="-3.14"
      upper="3.14"
      effort="100"
      velocity="100" />
  </joint>
  <link
    name="CoxisRM">
    <inertial>
      <origin
        xyz="0.00137051911451844 -0.0306273421624894 -0.0325655290539287"
        rpy="0 0 0" />
      <mass
        value="0.0500303933114246" />
      <inertia
        ixx="1.54884209684772E-05"
        ixy="2.10437946021079E-06"
        ixz="3.89316122356554E-08"
        iyy="1.61241827349089E-05"
        iyz="-2.22866155544161E-06"
        izz="1.4980725381487E-05" />
    </inertial>
    <visual>
      <origin
        xyz="0 0 0"
        rpy="0 0 0" />
      <geometry>
        <mesh
          filename="package://Scorpion_V3_FINAL/meshes/CoxisRM.stl" />
      </geometry>
      <material
        name="">
        <color
          rgba="0 0.27843137254902 0.890196078431372 1" />
      </material>
    </visual>
    <collision>
      <origin
        xyz="0 0 0"
        rpy="0 0 0" />
      <geometry>
        <mesh
          filename="package://Scorpion_V3_FINAL/meshes/CoxisRM.stl" />
      </geometry>
    </collision>
  </link>
  <joint
    name="CoxisRM_joint"
    type="revolute">
    <origin
      xyz="0.00166242657655533 -0.0859840824217421 -0.0159"
      rpy="3.14159265358979 0 3.14159265358979" />
    <parent
      link="base_link" />
    <child
      link="CoxisRM" />
    <axis
      xyz="0 0 -1" />
    <limit
      lower="-0.875"
      upper="0.875"
      effort="100"
      velocity="100" />
  </joint>
  <link
    name="FemurRM">
    <inertial>
      <origin
        xyz="0.032157947789468 -0.0136283830447929 -0.0364387890757428"
        rpy="0 0 0" />
      <mass
        value="0.103039112792354" />
      <inertia
        ixx="4.88087185509458E-05"
        ixy="2.17415435143644E-07"
        ixz="5.05034574022027E-07"
        iyy="4.91027991861452E-05"
        iyz="-1.2443496240265E-05"
        izz="1.99125303416937E-05" />
    </inertial>
    <visual>
      <origin
        xyz="0 0 0"
        rpy="0 0 0" />
      <geometry>
        <mesh
          filename="package://Scorpion_V3_FINAL/meshes/FemurRM.stl" />
      </geometry>
      <material
        name="">
        <color
          rgba="0.109803921568627 0.109803921568627 0.109803921568627 1" />
      </material>
    </visual>
    <collision>
      <origin
        xyz="0 0 0"
        rpy="0 0 0" />
      <geometry>
        <mesh
          filename="package://Scorpion_V3_FINAL/meshes/FemurRM.stl" />
      </geometry>
    </collision>
  </link>
  <joint
    name="FemurRM_joint"
    type="revolute">
    <origin
      xyz="-0.0294471720681494 -0.0605236621680384 -0.0335000009091112"
      rpy="-1.57079632679489 0 0" />
    <parent
      link="CoxisRM" />
    <child
      link="FemurRM" />
    <axis
      xyz="0.999847395799821 0 0.0174695481428791" />
    <limit
      lower="-3.14"
      upper="3.14"
      effort="100"
      velocity="100" />
  </joint>
  <link
    name="TibiaRM">
    <inertial>
      <origin
        xyz="0.0727699557496324 0.0304011988264136 0.0292054043444533"
        rpy="0 0 0" />
      <mass
        value="0.112635305891263" />
      <inertia
        ixx="3.96924433740149E-05"
        ixy="3.95227966594488E-06"
        ixz="-1.12510300076636E-05"
        iyy="4.71081199763216E-05"
        iyz="1.19676625660473E-06"
        izz="6.40653762834572E-05" />
    </inertial>
    <visual>
      <origin
        xyz="0 0 0"
        rpy="0 0 0" />
      <geometry>
        <mesh
          filename="package://Scorpion_V3_FINAL/meshes/TibiaRM.stl" />
      </geometry>
      <material
        name="">
        <color
          rgba="0.196078431372549 0.913725490196078 1 1" />
      </material>
    </visual>
    <collision>
      <origin
        xyz="0 0 0"
        rpy="0 0 0" />
      <geometry>
        <mesh
          filename="package://Scorpion_V3_FINAL/meshes/TibiaRM.stl" />
      </geometry>
    </collision>
  </link>
  <joint
    name="TibiaRM_joint"
    type="revolute">
    <origin
      xyz="0.00127862479180781 -0.026962651236027 -0.0731804656788009"
      rpy="0 0 -1.57079632679489" />
    <parent
      link="FemurRM" />
    <child
      link="TibiaRM" />
    <axis
      xyz="0 0.999847395799821 0.0174695481428742" />
    <limit
      lower="-3.14"
      upper="3.14"
      effort="100"
      velocity="100" />
  </joint>
  <link
    name="CoxisRB">
    <inertial>
      <origin
        xyz="0.00643111587121926 -0.0292884884943544 -0.0325440523411355"
        rpy="0 0 0" />
      <mass
        value="0.0489064207877058" />
      <inertia
        ixx="1.47765249630381E-05"
        ixy="1.88000022424408E-06"
        ixz="4.10698661830268E-07"
        iyy="1.6774543419591E-05"
        iyz="-2.19061870209153E-06"
        izz="1.49560881564061E-05" />
    </inertial>
    <visual>
      <origin
        xyz="0 0 0"
        rpy="0 0 0" />
      <geometry>
        <mesh
          filename="package://Scorpion_V3_FINAL/meshes/CoxisRB.stl" />
      </geometry>
      <material
        name="">
        <color
          rgba="0 0.27843137254902 0.890196078431372 1" />
      </material>
    </visual>
    <collision>
      <origin
        xyz="0 0 0"
        rpy="0 0 0" />
      <geometry>
        <mesh
          filename="package://Scorpion_V3_FINAL/meshes/CoxisRB.stl" />
      </geometry>
    </collision>
  </link>
  <joint
    name="CoxisRB_joint"
    type="revolute">
    <origin
      xyz="-0.0880450759860808 -0.065889779514333 -0.0159"
      rpy="3.14159265358979 0 3.14159265358979" />
    <parent
      link="base_link" />
    <child
      link="CoxisRB" />
    <axis
      xyz="0 0 -1" />
    <limit
      lower="-0.785"
      upper="0.785"
      effort="100"
      velocity="100" />
  </joint>
  <link
    name="FemurRB">
    <inertial>
      <origin
        xyz="0.0379611298329032 -0.00816993640651631 -0.0316819868484605"
        rpy="0 0 0" />
      <mass
        value="0.104163087334194" />
      <inertia
        ixx="4.77735690592534E-05"
        ixy="1.44824733206608E-06"
        ixz="5.76437955687924E-06"
        iyy="5.20283388772283E-05"
        iyz="-7.72464530094136E-06"
        izz="1.81083152181718E-05" />
    </inertial>
    <visual>
      <origin
        xyz="0 0 0"
        rpy="0 0 0" />
      <geometry>
        <mesh
          filename="package://Scorpion_V3_FINAL/meshes/FemurRB.stl" />
      </geometry>
      <material
        name="">
        <color
          rgba="0.109803921568627 0.109803921568627 0.109803921568627 1" />
      </material>
    </visual>
    <collision>
      <origin
        xyz="0 0 0"
        rpy="0 0 0" />
      <geometry>
        <mesh
          filename="package://Scorpion_V3_FINAL/meshes/FemurRB.stl" />
      </geometry>
    </collision>
  </link>
  <joint
    name="FemurRB_joint"
    type="revolute">
    <origin
      xyz="-0.0189212883839385 -0.0645928360557276 -0.0335000009091112"
      rpy="-1.57079632679489 0 0" />
    <parent
      link="CoxisRB" />
    <child
      link="FemurRB" />
    <axis
      xyz="0.982875036856407 0 0.184273334816833" />
    <limit
      lower="-3.14"
      upper="3.14"
      effort="100"
      velocity="100" />
  </joint>
  <link
    name="TibiaRB">
    <inertial>
      <origin
        xyz="0.0772929409056879 0.0325828451598749 -0.00606761273947959"
        rpy="0 0 0" />
      <mass
        value="0.112635346985893" />
      <inertia
        ixx="3.60247901962734E-05"
        ixy="2.99724960491081E-06"
        ixz="5.69295659972565E-06"
        iyy="4.80719654666445E-05"
        iyz="-4.28387273069876E-06"
        izz="6.67692191206341E-05" />
    </inertial>
    <visual>
      <origin
        xyz="0 0 0"
        rpy="0 0 0" />
      <geometry>
        <mesh
          filename="package://Scorpion_V3_FINAL/meshes/TibiaRB.stl" />
      </geometry>
      <material
        name="">
        <color
          rgba="0.196078431372549 0.913725490196078 1 1" />
      </material>
    </visual>
    <collision>
      <origin
        xyz="0 0 0"
        rpy="0 0 0" />
      <geometry>
        <mesh
          filename="package://Scorpion_V3_FINAL/meshes/TibiaRB.stl" />
      </geometry>
    </collision>
  </link>
  <joint
    name="TibiaRB_joint"
    type="revolute">
    <origin
      xyz="0.0140544011955745 -0.016339872810639 -0.0749632067321428"
      rpy="0 0 -1.57079632679489" />
    <parent
      link="FemurRB" />
    <child
      link="TibiaRB" />
    <axis
      xyz="0 0.982875036856409 0.184273334816823" />
    <limit
      lower="-3.14"
      upper="3.14"
      effort="100"
      velocity="100" />
  </joint>
  <link
    name="CoxisLU">
    <inertial>
      <origin
        xyz="-0.00144684016636547 -0.0299513176185721 -0.0325440506435633"
        rpy="0 0 0" />
      <mass
        value="0.0489064189132023" />
      <inertia
        ixx="1.54517415914159E-05"
        ixy="-2.10418271477098E-06"
        ixz="-3.8905701989502E-08"
        iyy="1.60993260323347E-05"
        iyz="-2.22844685767864E-06"
        izz="1.49560867841428E-05" />
    </inertial>
    <visual>
      <origin
        xyz="0 0 0"
        rpy="0 0 0" />
      <geometry>
        <mesh
          filename="package://Scorpion_V3_FINAL/meshes/CoxisLU.stl" />
      </geometry>
      <material
        name="">
        <color
          rgba="0 0.27843137254902 0.890196078431372 1" />
      </material>
    </visual>
    <collision>
      <origin
        xyz="0 0 0"
        rpy="0 0 0" />
      <geometry>
        <mesh
          filename="package://Scorpion_V3_FINAL/meshes/CoxisLU.stl" />
      </geometry>
    </collision>
  </link>
  <joint
    name="CoxisLU_joint"
    type="revolute">
    <origin
      xyz="0.0883681152485222 0.0658954181790695 -0.0149"
      rpy="-3.14159265358979 0 0" />
    <parent
      link="base_link" />
    <child
      link="CoxisLU" />
    <axis
      xyz="0 0 -1" />
    <limit
      lower="-0.785"
      upper="0.785"
      effort="100"
      velocity="100" />
  </joint>
  <link
    name="FemurLU">
    <inertial>
      <origin
        xyz="-0.0314681080381053 -0.0389999999987984 0.000549277868330034"
        rpy="0 0 0" />
      <mass
        value="0.104163087334194" />
      <inertia
        ixx="4.88557777208909E-05"
        ixy="-5.07793350836555E-12"
        ixz="8.47762640188344E-08"
        iyy="1.53433185752301E-05"
        iyz="-2.90914613738233E-10"
        izz="5.37111268585325E-05" />
    </inertial>
    <visual>
      <origin
        xyz="0 0 0"
        rpy="0 0 0" />
      <geometry>
        <mesh
          filename="package://Scorpion_V3_FINAL/meshes/FemurLU.stl" />
      </geometry>
      <material
        name="">
        <color
          rgba="0.109803921568627 0.109803921568627 0.109803921568627 1" />
      </material>
    </visual>
    <collision>
      <origin
        xyz="0 0 0"
        rpy="0 0 0" />
      <geometry>
        <mesh
          filename="package://Scorpion_V3_FINAL/meshes/FemurLU.stl" />
      </geometry>
    </collision>
  </link>
  <joint
    name="FemurLU_joint"
    type="revolute">
    <origin
      xyz="0.0294482110285378 -0.0605231573305991 -0.0334999990908888"
      rpy="-1.5707963267949 0 0" />
    <parent
      link="CoxisLU" />
    <child
      link="FemurLU" />
    <axis
      xyz="-0.999847695156391 0 0.0174524064372951" />
    <limit
      lower="-3.14"
      upper="3.14"
      effort="100"
      velocity="100" />
  </joint>
  <link
    name="TibiaLU">
    <inertial>
      <origin
        xyz="0.0775722120207263 -0.0310765644223914 -0.0094580892518071"
        rpy="0 0 0" />
      <mass
        value="0.112635359398953" />
      <inertia
        ixx="3.57790819176825E-05"
        ixy="-3.93225091191521E-06"
        ixz="4.2637271913671E-06"
        iyy="4.71798556862518E-05"
        iyz="8.90598957856701E-07"
        izz="6.79070387405214E-05" />
    </inertial>
    <visual>
      <origin
        xyz="0 0 0"
        rpy="0 0 0" />
      <geometry>
        <mesh
          filename="package://Scorpion_V3_FINAL/meshes/TibiaLU.stl" />
      </geometry>
      <material
        name="">
        <color
          rgba="0.196078431372549 0.913725490196078 1 1" />
      </material>
    </visual>
    <collision>
      <origin
        xyz="0 0 0"
        rpy="0 0 0" />
      <geometry>
        <mesh
          filename="package://Scorpion_V3_FINAL/meshes/TibiaLU.stl" />
      </geometry>
    </collision>
  </link>
  <joint
    name="TibiaLU_joint"
    type="revolute">
    <origin
      xyz="0 -0.078 0"
      rpy="0 0 -1.5707963267949" />
    <parent
      link="FemurLU" />
    <child
      link="TibiaLU" />
    <axis
      xyz="0 -0.999847695156391 0.0174524064372955" />
    <limit
      lower="-3.14"
      upper="3.14"
      effort="100"
      velocity="100" />
  </joint>
  <link
    name="CoxisLM">
    <inertial>
      <origin
        xyz="-0.00390877231649847 -0.0297303931837618 -0.0325440511343324"
        rpy="0 0 0" />
      <mass
        value="0.0489064204454596" />
      <inertia
        ixx="1.51107036869505E-05"
        ixy="-2.02248003860144E-06"
        ixz="-2.22312163114164E-07"
        iyy="1.64403659746689E-05"
        iyz="-2.21767126009945E-06"
        izz="1.49560875032864E-05" />
    </inertial>
    <visual>
      <origin
        xyz="0 0 0"
        rpy="0 0 0" />
      <geometry>
        <mesh
          filename="package://Scorpion_V3_FINAL/meshes/CoxisLM.stl" />
      </geometry>
      <material
        name="">
        <color
          rgba="0 0.27843137254902 0.890196078431372 1" />
      </material>
    </visual>
    <collision>
      <origin
        xyz="0 0 0"
        rpy="0 0 0" />
      <geometry>
        <mesh
          filename="package://Scorpion_V3_FINAL/meshes/CoxisLM.stl" />
      </geometry>
    </collision>
  </link>
  <joint
    name="CoxisLM_joint"
    type="revolute">
    <origin
      xyz="-0.00133938732850295 0.0859897210928646 -0.0149"
      rpy="-3.14159265358979 0 0" />
    <parent
      link="base_link" />
    <child
      link="CoxisLM" />
    <axis
      xyz="0 0 -1" />
    <limit
      lower="-0.785"
      upper="0.785"
      effort="100"
      velocity="100" />
  </joint>
  <link
    name="FemurLM">
    <inertial>
      <origin
        xyz="-0.0351225735988011 0.00802956274031282 -0.0348349605387908"
        rpy="0 0 0" />
      <mass
        value="0.104163087334194" />
      <inertia
        ixx="4.8537096232152E-05"
        ixy="7.71024841382912E-07"
        ixz="-3.16434762510979E-06"
        iyy="5.2085795562812E-05"
        iyz="7.69160607127433E-06"
        izz="1.72873313596896E-05" />
    </inertial>
    <visual>
      <origin
        xyz="0 0 0"
        rpy="0 0 0" />
      <geometry>
        <mesh
          filename="package://Scorpion_V3_FINAL/meshes/FemurLM.stl" />
      </geometry>
      <material
        name="">
        <color
          rgba="0.109803921568627 0.109803921568627 0.109803921568627 1" />
      </material>
    </visual>
    <collision>
      <origin
        xyz="0 0 0"
        rpy="0 0 0" />
      <geometry>
        <mesh
          filename="package://Scorpion_V3_FINAL/meshes/FemurLM.stl" />
      </geometry>
    </collision>
  </link>
  <joint
    name="FemurLM_link"
    type="revolute">
    <origin
      xyz="0.024363356560284 -0.0627429403452071 -0.0334999990908888"
      rpy="-1.5707963267949 0 0" />
    <parent
      link="CoxisLM" />
    <child
      link="FemurLM" />
    <axis
      xyz="-0.995013283945232 0 0.099742492311579" />
    <limit
      lower="-3.14"
      upper="3.14"
      effort="100"
      velocity="100" />
  </joint>
  <link
    name="TibiaLM">
    <inertial>
      <origin
        xyz="0.0782139490595376 -0.0307610040047967 0.00299929592834661"
        rpy="0 0 0" />
      <mass
        value="0.11263538310695" />
      <inertia
        ixx="3.5240932701602E-05"
        ixy="-4.01895708544886E-06"
        ixz="4.19172052212361E-07"
        iyy="4.73703521455253E-05"
        iyz="2.13130302089116E-06"
        izz="6.82547094382413E-05" />
    </inertial>
    <visual>
      <origin
        xyz="0 0 0"
        rpy="0 0 0" />
      <geometry>
        <mesh
          filename="package://Scorpion_V3_FINAL/meshes/TibiaLM.stl" />
      </geometry>
      <material
        name="">
        <color
          rgba="0.196078431372549 0.913725490196078 1 1" />
      </material>
    </visual>
    <collision>
      <origin
        xyz="0 0 0"
        rpy="0 0 0" />
      <geometry>
        <mesh
          filename="package://Scorpion_V3_FINAL/meshes/TibiaLM.stl" />
      </geometry>
    </collision>
  </link>
  <joint
    name="TibiaLM_joint"
    type="revolute">
    <origin
      xyz="-0.00761323701713537 0.0160591254782219 -0.075948292350755"
      rpy="0 0 -1.5707963267949" />
    <parent
      link="FemurLM" />
    <child
      link="TibiaLM" />
    <axis
      xyz="0 -0.995013283945232 0.099742492311578" />
    <limit
      lower="-3.14"
      upper="3.14"
      effort="100"
      velocity="100" />
  </joint>
  <link
    name="Lidar">
    <inertial>
      <origin
        xyz="9.67219649283396E-05 8.02637664281403E-05 -0.0168127720712705"
        rpy="0 0 0" />
      <mass
        value="0.0120321645563741" />
      <inertia
        ixx="2.21545778487584E-06"
        ixy="-3.25402195329891E-08"
        ixz="4.77244799718717E-09"
        iyy="2.13781008400087E-06"
        iyz="4.27418713121665E-09"
        izz="3.87805340358154E-06" />
    </inertial>
    <visual>
      <origin
        xyz="0 0 0"
        rpy="0 0 0" />
      <geometry>
        <mesh
          filename="package://Scorpion_V3_FINAL/meshes/Lidar.stl" />
      </geometry>
      <material
        name="">
        <color
          rgba="0.498039215686275 0.498039215686275 0.498039215686275 1" />
      </material>
    </visual>
    <collision>
      <origin
        xyz="0 0 0"
        rpy="0 0 0" />
      <geometry>
        <mesh
          filename="package://Scorpion_V3_FINAL/meshes/Lidar.stl" />
      </geometry>
    </collision>
  </link>
  <joint
    name="Lidar_joint"
    type="fixed">
    <origin
      xyz="0.00016152 0 0.10824"
      rpy="0 0 0" />
    <parent
      link="base_link" />
    <child
      link="Lidar" />
    <axis
      xyz="0 0 0" />
  </joint>
  <link
    name="Cola">
    <inertial>
      <origin
        xyz="-0.0155030252650207 0.0492438688660397 -0.00384481344660556"
        rpy="0 0 0" />
      <mass
        value="0.0509856311845363" />
      <inertia
        ixx="1.51462202376911E-05"
        ixy="9.62479414829148E-07"
        ixz="-7.64171219704307E-08"
        iyy="7.1768181465111E-06"
        iyz="1.94254222755466E-08"
        izz="1.86143874056638E-05" />
    </inertial>
    <visual>
      <origin
        xyz="0 0 0"
        rpy="0 0 0" />
      <geometry>
        <mesh
          filename="package://Scorpion_V3_FINAL/meshes/Cola.stl" />
      </geometry>
      <material
        name="">
        <color
          rgba="1 0.572549019607843 0.345098039215686 1" />
      </material>
    </visual>
    <collision>
      <origin
        xyz="0 0 0"
        rpy="0 0 0" />
      <geometry>
        <mesh
          filename="package://Scorpion_V3_FINAL/meshes/Cola.stl" />
      </geometry>
    </collision>
  </link>
  <joint
    name="Cola_joint"
    type="revolute">
    <origin
      xyz="-0.17379 -0.019636 0.1715"
      rpy="1.5708 0 -1.5533" />
    <parent
      link="base_link" />
    <child
      link="Cola" />
    <axis
      xyz="-1 0 0" />
    <limit
      lower="-3.14"
      upper="3.14"
      effort="100"
      velocity="100" />
  </joint>
  <link
    name="camera">
    <inertial>
      <origin
        xyz="-0.00138241299653236 -6.95335166951278E-05 0.0139507475592652"
        rpy="0 0 0" />
      <mass
        value="0.00708886280729394" />
      <inertia
        ixx="8.65829199775099E-07"
        ixy="3.84043675210179E-09"
        ixz="-1.26584192519496E-08"
        iyy="6.32844058283521E-07"
        iyz="-1.33544565959627E-09"
        izz="4.30459897220327E-07" />
    </inertial>
    <visual>
      <origin
        xyz="0 0 0"
        rpy="0 0 0" />
      <geometry>
        <mesh
          filename="package://Scorpion_V3_FINAL/meshes/camera.stl" />
      </geometry>
      <material
        name="">
        <color
          rgba="0.211764705882353 0.211764705882353 0.211764705882353 1" />
      </material>
    </visual>
    <collision>
      <origin
        xyz="0 0 0"
        rpy="0 0 0" />
      <geometry>
        <mesh
          filename="package://Scorpion_V3_FINAL/meshes/camera.stl" />
      </geometry>
    </collision>
  </link>
  <joint
    name="camera_joint"
    type="revolute">
    <origin
      xyz="-0.02149 0.10706 -0.016671"
      rpy="-1.5708 1.5533 0" />
    <parent
      link="Cola" />
    <child
      link="camera" />
    <axis
      xyz="0 0 -1" />
    <limit
      lower="-3.14"
      upper="3.14"
      effort="100"
      velocity="100" />
  </joint>
  <link
    name="CoxisLB">
    <inertial>
      <origin
        xyz="-0.0207139896555791 -0.0216819152954048 -0.032544052506396"
        rpy="0 0 0" />
      <mass
        value="0.0489064243813936" />
      <inertia
        ixx="1.36467048451567E-05"
        ixy="2.23370762695659E-08"
        ixz="-1.48922788525084E-06"
        iyy="1.79043681755995E-05"
        iyz="-1.65821812492883E-06"
        izz="1.49560888027347E-05" />
    </inertial>
    <visual>
      <origin
        xyz="0 0 0"
        rpy="0 0 0" />
      <geometry>
        <mesh
          filename="package://Scorpion_V3_FINAL/meshes/CoxisLB.stl" />
      </geometry>
      <material
        name="">
        <color
          rgba="0 0.27843137254902 0.890196078431372 1" />
      </material>
    </visual>
    <collision>
      <origin
        xyz="0 0 0"
        rpy="0 0 0" />
      <geometry>
        <mesh
          filename="package://Scorpion_V3_FINAL/meshes/CoxisLB.stl" />
      </geometry>
    </collision>
  </link>
  <joint
    name="CoxisLB_joint"
    type="revolute">
    <origin
      xyz="-0.090291 0.062777 -0.0149"
      rpy="-3.1416 0 0" />
    <parent
      link="base_link" />
    <child
      link="CoxisLB" />
    <axis
      xyz="0 0 -1" />
    <limit
      lower="-0.785"
      upper="0.785"
      effort="100"
      velocity="100" />
  </joint>
  <link
    name="FemurLB">
    <inertial>
      <origin
        xyz="-0.0481528559020931 0.0122639913306611 -0.0065146385061148"
        rpy="0 0 0" />
      <mass
        value="0.104163087334194" />
      <inertia
        ixx="3.55870736459804E-05"
        ixy="7.65278139080282E-06"
        ixz="-1.47727974338018E-05"
        iyy="4.99180755370344E-05"
        iyz="8.52122393784387E-06"
        izz="3.24050739716386E-05" />
    </inertial>
    <visual>
      <origin
        xyz="0 0 0"
        rpy="0 0 0" />
      <geometry>
        <mesh
          filename="package://Scorpion_V3_FINAL/meshes/FemurLB.stl" />
      </geometry>
      <material
        name="">
        <color
          rgba="0.109803921568627 0.109803921568627 0.109803921568627 1" />
      </material>
    </visual>
    <collision>
      <origin
        xyz="0 0 0"
        rpy="0 0 0" />
      <geometry>
        <mesh
          filename="package://Scorpion_V3_FINAL/meshes/FemurLB.stl" />
      </geometry>
    </collision>
  </link>
  <joint
    name="FemurLB_joint"
    type="revolute">
    <origin
      xyz="-0.017399 -0.06502 -0.0335"
      rpy="-1.5708 0 0" />
    <parent
      link="CoxisLB" />
    <child
      link="FemurLB" />
    <axis
      xyz="-0.744 0 0.66818" />
    <limit
      lower="-0.785"
      upper="0.785"
      effort="100"
      velocity="100" />
  </joint>
  <link
    name="TibiaLB">
    <inertial>
      <origin
        xyz="0.0782139490599018 -0.0230507229082996 0.0205888153324407"
        rpy="0 0 0" />
      <mass
        value="0.112635383099301" />
      <inertia
        ixx="3.52409326987584E-05"
        ixy="-2.99547003178654E-06"
        ixz="2.71198830049099E-06"
        iyy="5.66874769994262E-05"
        iyz="1.05979149557691E-05"
        izz="5.89375845796022E-05" />
    </inertial>
    <visual>
      <origin
        xyz="0 0 0"
        rpy="0 0 0" />
      <geometry>
        <mesh
          filename="package://Scorpion_V3_FINAL/meshes/TibiaLB.stl" />
      </geometry>
      <material
        name="">
        <color
          rgba="0.196078431372549 0.913725490196078 1 1" />
      </material>
    </visual>
    <collision>
      <origin
        xyz="0 0 0"
        rpy="0 0 0" />
      <geometry>
        <mesh
          filename="package://Scorpion_V3_FINAL/meshes/TibiaLB.stl" />
      </geometry>
    </collision>
  </link>
  <joint
    name="TibiaLB_joint"
    type="revolute">
    <origin
      xyz="-0.049474 0.024528 -0.055088"
      rpy="0 0 -1.5708" />
    <parent
      link="FemurLB" />
    <child
      link="TibiaLB" />
    <axis
      xyz="0 -0.744 0.66818" />
    <limit
      lower="-0.785"
      upper="0.785"
      effort="100"
      velocity="100" />
  </joint>
</robot>